2021-02-24 14:25:41,150 - urllib3.connectionpool - DEBUG - Starting new HTTP connection (1): api.openweathermap.org:80
2021-02-24 14:25:41,442 - urllib3.connectionpool - DEBUG - http://api.openweathermap.org:80 "GET /data/2.5/forecast?q=MINFEF%2CES&units=imperial&appid=9bf1e923dece77aa4efe3e64a779da53 HTTP/1.1" 404 40
2021-02-24 14:25:41,445 - root - ERROR - Error decoding respose into JSON
Traceback (most recent call last):
  File "C:\Users\nicke\Desktop\Software Development\Capstone\Lab7\weather_forecast.py", line 37, in get_wx_data
    response.raise_for_status()  # Raise exception for 400 or 500 errors
  File "C:\Users\nicke\AppData\Local\Programs\Python\Python39\lib\site-packages\requests\models.py", line 943, in raise_for_status
    raise HTTPError(http_error_msg, response=self)
requests.exceptions.HTTPError: 404 Client Error: Not Found for url: http://api.openweathermap.org/data/2.5/forecast?q=MINFEF%2CES&units=imperial&appid=9bf1e923dece77aa4efe3e64a779da53
2021-02-24 20:28:41,017 - urllib3.connectionpool - DEBUG - Starting new HTTP connection (1): api.openweathermap.org:80
2021-02-24 20:28:41,277 - urllib3.connectionpool - DEBUG - http://api.openweathermap.org:80 "GET /data/2.5/forecast?q=SAINT+LOUIS%2CUS&units=imperial&appid=9bf1e923dece77aa4efe3e64a779da53 HTTP/1.1" 200 15382
